Workbook

Sheet Legende
A1: SUIVI DE SAISON U18 - JOURNAL CONTINU
A3: Principe
A4: Un seul classeur pour toute la saison, pour les deux effectifs (Équipe 1 et Équipe 2). Chaque match reçoit un numéro ("N° Match") dans l'onglet Matchs, reporté ensuite dans les autres onglets pour rattacher chaque ligne (convocation, but, carton, changement) au bon match. Les stats de saison et le suivi des renforts se mettent à jour tout seuls.
A6: Effectif Saison | B6: Liste unique des joueurs des deux équipes, avec leur équipe habituelle (Équipe 1 / Équipe 2), saisie une fois en début de saison.
A8: Matchs | B8: Un match = une ligne. Le N° Match est automatique. Le nombre de convoqués et le nombre de renforts venus de l'Équipe 1 se calculent seuls, avec une alerte si vous dépassez 14 convoqués. Renseignez "Niveau adversaire" et "Classement adversaire" (manuel, facultatif) : un bilan victoires/nuls/défaites par niveau se calcule automatiquement à droite du tableau.
A10: Convocations & Temps de jeu | B10: Une ligne par passage sur le terrain. Un joueur qui sort et rentre plusieurs fois (courant en U18) prend simplement une ligne de plus pour le même match. La colonne "Équipe habituelle" repère automatiquement les renforts de l'Équipe 1.
A12: Buts | B12: Une ligne par but, rattachée à un N° Match. Le type de but se choisit dans une liste (Jeu, Tête, Penalty, Coup franc, CSC, Autre).
A14: Cartons | B14: Une ligne par carton, rattachée à un N° Match.
A16: Changements | B16: Journal désormais 100% automatique : reconstruit à partir de l'onglet "Convocations & Temps de jeu" (Minute entrée / Minute sortie), pour garder une trace chronologique lisible sans ressaisir les changements. Rien à remplir dans cet onglet. Le rapprochement Sort/Entre se fait par match + minute (et par ordre en cas de plusieurs changements à la même minute).
A18: Gardien | B18: Une ligne par match (deux lignes si deux gardiens se sont partagé la rencontre). Le clean sheet et le contrôle vs score encaissé se calculent seuls ; ces stats remontent aussi dans le Cumul Saison (matchs gardés, clean sheets, buts encaissés).
A20: Cumul Saison | B20: 100% automatique : totaux par joueur (équipe habituelle, matchs joués, buts, passes, cartons, temps de jeu), quelle que soit l'équipe pour laquelle il a joué. Inclut aussi le taux de convocation/titularisation, le temps de jeu moyen, l'historique des motifs d'absence, et pour les gardiens : matchs gardés, clean sheets, buts encaissés.
A23: Suivi des renforts
A25: Ce classeur suit les convocations de l'Équipe 2. Un joueur de l'Équipe 1 appelé en renfort apparaît normalement dans "Convocations & Temps de jeu" comme n'importe quel joueur : la colonne "Équipe habituelle" le repère automatiquement (grâce à l'onglet Effectif Saison), et l'onglet Matchs compte le nombre de renforts par match. Ses stats individuelles (buts, passes, temps de jeu) restent suivies comme celles de tout autre joueur dans le Cumul Saison.
A27: A savoir
A29: • | B29: Choisissez toujours le joueur dans la liste déroulante (ne retapez pas son nom à la main) : cela garantit que les stats de saison et le suivi des renforts le retrouvent correctement.
A30: • | B30: Le N° Match se choisit aussi dans une liste déroulante, alimentée par l'onglet Matchs.
A31: • | B31: Un joueur qui sort et rentre plusieurs fois dans le même match (fréquent en U18) prend une ligne par passage dans "Convocations & Temps de jeu" : même N° Match, même joueur, juste un "N° de passage" différent (1, 2, 3...). Le temps de jeu total du joueur additionne alors tous ses passages, sur tous les matchs.
A32: • | B32: Pour ajouter un match au-delà du numéro 30, ou un joueur au-delà de 30, il suffit d'étirer les formules d'une ligne vers le bas.
A34: Code couleur
A36: Exemple | B36: Texte bleu : cellule à remplir manuellement
A37: Exemple | B37: Texte noir : cellule calculée automatiquement (ne pas modifier)
A38: Exemple | B38: Fond jaune pâle : ligne d'exemple, à remplacer par vos données
A39: Exemple | B39: Fond jaune vif : cellule clé (ex. durée du match)
A40: Exemple | B40: Fond rouge : alerte (ex. plus de 14 joueurs convoqués)

Sheet Effectif Saison
A1: EFFECTIF SAISON (EQUIPE 1 + EQUIPE 2)
A3: Nom | B3: Prénom | C3: Poste | D3: Équipe | E3: Nom complet
A4: MICHON | B4: Alan | D4: Équipe 1 | E4: =IF(B4="","",B4&" "&A4) -> Alan MICHON
A5: BRUNTZ | B5: Jean | D5: Équipe 1 | E5: =IF(B5="","",B5&" "&A5) -> Jean BRUNTZ
A6: SBK | B6: Marouane | D6: Équipe 1 | E6: =IF(B6="","",B6&" "&A6) -> Marouane SBK
A7: BIHL | B7: Noé | D7: Équipe 1 | E7: =IF(B7="","",B7&" "&A7) -> Noé BIHL
A8: COLAIANNI | B8: Luca | D8: Équipe 1 | E8: =IF(B8="","",B8&" "&A8) -> Luca COLAIANNI
A9: ER | B9: Atilla | D9: Équipe 1 | E9: =IF(B9="","",B9&" "&A9) -> Atilla ER
A10: BUHR | B10: Lucas | D10: Équipe 1 | E10: =IF(B10="","",B10&" "&A10) -> Lucas BUHR
A11: HOUX | B11: Yanis | D11: Équipe 1 | E11: =IF(B11="","",B11&" "&A11) -> Yanis HOUX
A12: COLAIANNI | B12: Tino | D12: Équipe 1 | E12: =IF(B12="","",B12&" "&A12) -> Tino COLAIANNI
A13: KELLERKNECHT | B13: Achille | D13: Équipe 1 | E13: =IF(B13="","",B13&" "&A13) -> Achille KELLERKNECHT
A14: LEPERT | B14: Charly | D14: Équipe 1 | E14: =IF(B14="","",B14&" "&A14) -> Charly LEPERT
A15: STANGRET | B15: Basile | D15: Équipe 1 | E15: =IF(B15="","",B15&" "&A15) -> Basile STANGRET
... A41: WIOLAND | B41: Anthony | D41: Équipe 2 | E41: =IF(B41="","",B41&" "&A41) -> Anthony WIOLAND
E42: =IF(B42="","",B42&" "&A42)
E43: =IF(B43="","",B43&" "&A43)
E44: =IF(B44="","",B44&" "&A44)
E45: =IF(B45="","",B45&" "&A45)
E46: =IF(B46="","",B46&" "&A46)
E47: =IF(B47="","",B47&" "&A47)
E48: =IF(B48="","",B48&" "&A48)
E49: =IF(B49="","",B49&" "&A49)
E50: =IF(B50="","",B50&" "&A50)
E51: =IF(B51="","",B51&" "&A51)

Sheet Matchs
A1: MATCHS DE LA SAISON (EQUIPE 2) | O1: Bilan par niveau d'adversaire (100% automatique)
A3: N° Match | B3: Date | C3: Adversaire | D3: Compétition | E3: Lieu | F3: Durée (min) | G3: Score Nous | H3: Score Adverse | I3: Convoqués | J3: Dont renforts Éq.1 | K3: Alerte | L3: Niveau adversaire | M3: Classement adversaire | O3: Niveau | P3: Matchs joués (score renseigné) | Q3: Victoires | R3: Nuls | S3: Défaites | T3: % Victoires
A4: =ROW()-3 -> 1 | I4: =COUNTIFS('Convocations & Temps de jeu'!$A$4:$A$675,A4,'Convocations & Temps de jeu'!$C$4:$C$675,"Oui") -> 0 | J4: =COUNTIFS('Convocations & Temps de jeu'!$A$4:$A$675,A4,'Convocations & Temps de jeu'!$C$4:$C$675,"Oui",'Convocations & Temps de jeu'!$G$4:$G$675,"Équipe 1") -> 0 | K4: =IF(I4>14,"⚠ Plus de 14 convoqués","") | O4: Plus fort | P4: =Q4+R4+S4 -> 0 | Q4: =SUMPRODUCT(($L$4:$L$31=O4)*($G$4:$G$31>$H$4:$H$31)*ISNUMBER($G$4:$G$31)*ISNUMBER($H$4:$H$31)) -> 0 | R4: =SUMPRODUCT(($L$4:$L$31=O4)*($G$4:$G$31=$H$4:$H$31)*ISNUMBER($G$4:$G$31)*ISNUMBER($H$4:$H$31)) -> 0 | S4: =SUMPRODUCT(($L$4:$L$31=O4)*($G$4:$G$31<$H$4:$H$31)*ISNUMBER($G$4:$G$31)*ISNUMBER($H$4:$H$31)) -> 0 | T4: =IF(P4=0,"",Q4/P4)
A5: =ROW()-3 -> 2 | G5: =IF(B5="","",COUNTIFS(Buts!$A$4:$A$151,A5,Buts!$E$4:$E$151,"Nous")) | H5: =IF(B5="","",COUNTIFS(Buts!$A$4:$A$151,A5,Buts!$E$4:$E$151,"Adverse")) | I5: =IF(B5="","",COUNTIFS('Convocations & Temps de jeu'!$A$4:$A$675,A5,'Convocations & Temps de jeu'!$C$4:$C$675,"Oui")) | J5: =IF(B5="","",COUNTIFS('Convocations & Temps de jeu'!$A$4:$A$675,A5,'Convocations & Temps de jeu'!$C$4:$C$675,"Oui",'Convocations & Temps de jeu'!$G$4:$G$675,"Équipe 1")) | K5: =IF(I5="","",IF(I5>14,"⚠ Plus de 14 convoqués","")) | O5: Similaire | P5: =Q5+R5+S5 -> 0 | Q5: =SUMPRODUCT(($L$4:$L$31=O5)*($G$4:$G$31>$H$4:$H$31)*ISNUMBER($G$4:$G$31)*ISNUMBER($H$4:$H$31)) -> 0 | R5: =SUMPRODUCT(($L$4:$L$31=O5)*($G$4:$G$31=$H$4:$H$31)*ISNUMBER($G$4:$G$31)*ISNUMBER($H$4:$H$31)) -> 0 | S5: =SUMPRODUCT(($L$4:$L$31=O5)*($G$4:$G$31<$H$4:$H$31)*ISNUMBER($G$4:$G$31)*ISNUMBER($H$4:$H$31)) -> 0 | T5: =IF(P5=0,"",Q5/P5)
A6: =ROW()-3 -> 3 | G6: =IF(B6="","",COUNTIFS(Buts!$A$4:$A$151,A6,Buts!$E$4:$E$151,"Nous")) | H6: =IF(B6="","",COUNTIFS(Buts!$A$4:$A$151,A6,Buts!$E$4:$E$151,"Adverse")) | I6: =IF(B6="","",COUNTIFS('Convocations & Temps de jeu'!$A$4:$A$675,A6,'Convocations & Temps de jeu'!$C$4:$C$675,"Oui")) | J6: =IF(B6="","",COUNTIFS('Convocations & Temps de jeu'!$A$4:$A$675,A6,'Convocations & Temps de jeu'!$C$4:$C$675,"Oui",'Convocations & Temps de jeu'!$G$4:$G$675,"Équipe 1")) | K6: =IF(I6="","",IF(I6>14,"⚠ Plus de 14 convoqués","")) | O6: Plus faible | P6: =Q6+R6+S6 -> 0 | Q6: =SUMPRODUCT(($L$4:$L$31=O6)*($G$4:$G$31>$H$4:$H$31)*ISNUMBER($G$4:$G$31)*ISNUMBER($H$4:$H$31)) -> 0 | R6: =SUMPRODUCT(($L$4:$L$31=O6)*($G$4:$G$31=$H$4:$H$31)*ISNUMBER($G$4:$G$31)*ISNUMBER($H$4:$H$31)) -> 0 | S6: =SUMPRODUCT(($L$4:$L$31=O6)*($G$4:$G$31<$H$4:$H$31)*ISNUMBER($G$4:$G$31)*ISNUMBER($H$4:$H$31)) -> 0 | T6: =IF(P6=0,"",Q6/P6)
A7: =ROW()-3 -> 4 | G7: =IF(B7="","",COUNTIFS(Buts!$A$4:$A$151,A7,Buts!$E$4:$E$151,"Nous")) | H7: =IF(B7="","",COUNTIFS(Buts!$A$4:$A$151,A7,Buts!$E$4:$E$151,"Adverse")) | I7: =IF(B7="","",COUNTIFS('Convocations & Temps de jeu'!$A$4:$A$675,A7,'Convocations & Temps de jeu'!$C$4:$C$675,"Oui")) | J7: =IF(B7="","",COUNTIFS('Convocations & Temps de jeu'!$A$4:$A$675,A7,'Convocations & Temps de jeu'!$C$4:$C$675,"Oui",'Convocations & Temps de jeu'!$G$4:$G$675,"Équipe 1")) | K7: =IF(I7="","",IF(I7>14,"⚠ Plus de 14 convoqués","")) | O7: Inconnu | P7: =Q7+R7+S7 -> 0 | Q7: =SUMPRODUCT(($L$4:$L$31=O7)*($G$4:$G$31>$H$4:$H$31)*ISNUMBER($G$4:$G$31)*ISNUMBER($H$4:$H$31)) -> 0 | R7: =SUMPRODUCT(($L$4:$L$31=O7)*($G$4:$G$31=$H$4:$H$31)*ISNUMBER($G$4:$G$31)*ISNUMBER($H$4:$H$31)) -> 0 | S7: =SUMPRODUCT(($L$4:$L$31=O7)*($G$4:$G$31<$H$4:$H$31)*ISNUMBER($G$4:$G$31)*ISNUMBER($H$4:$H$31)) -> 0 | T7: =IF(P7=0,"",Q7/P7)
A8: =ROW()-3 -> 5 | G8: =IF(B8="","",COUNTIFS(Buts!$A$4:$A$151,A8,Buts!$E$4:$E$151,"Nous")) | H8: =IF(B8="","",COUNTIFS(Buts!$A$4:$A$151,A8,Buts!$E$4:$E$151,"Adverse")) | I8: =IF(B8="","",COUNTIFS('Convocations & Temps de jeu'!$A$4:$A$675,A8,'Convocations & Temps de jeu'!$C$4:$C$675,"Oui")) | J8: =IF(B8="","",COUNTIFS('Convocations & Temps de jeu'!$A$4:$A$675,A8,'Convocations & Temps de jeu'!$C$4:$C$675,"Oui",'Convocations & Temps de jeu'!$G$4:$G$675,"Équipe 1")) | K8: =IF(I8="","",IF(I8>14,"⚠ Plus de 14 convoqués",""))
A9: =ROW()-3 -> 6 | G9: =IF(B9="","",COUNTIFS(Buts!$A$4:$A$151,A9,Buts!$E$4:$E$151,"Nous")) | H9: =IF(B9="","",COUNTIFS(Buts!$A$4:$A$151,A9,Buts!$E$4:$E$151,"Adverse")) | I9: =IF(B9="","",COUNTIFS('Convocations & Temps de jeu'!$A$4:$A$675,A9,'Convocations & Temps de jeu'!$C$4:$C$675,"Oui")) | J9: =IF(B9="","",COUNTIFS('Convocations & Temps de jeu'!$A$4:$A$675,A9,'Convocations & Temps de jeu'!$C$4:$C$675,"Oui",'Convocations & Temps de jeu'!$G$4:$G$675,"Équipe 1")) | K9: =IF(I9="","",IF(I9>14,"⚠ Plus de 14 convoqués",""))
A10: =ROW()-3 -> 7 | G10: =IF(B10="","",COUNTIFS(Buts!$A$4:$A$151,A10,Buts!$E$4:$E$151,"Nous")) | H10: =IF(B10="","",COUNTIFS(Buts!$A$4:$A$151,A10,Buts!$E$4:$E$151,"Adverse")) | I10: =IF(B10="","",COUNTIFS('Convocations & Temps de jeu'!$A$4:$A$675,A10,'Convocations & Temps de jeu'!$C$4:$C$675,"Oui")) | J10: =IF(B10="","",COUNTIFS('Convocations & Temps de jeu'!$A$4:$A$675,A10,'Convocations & Temps de jeu'!$C$4:$C$675,"Oui",'Convocations & Temps de jeu'!$G$4:$G$675,"Équipe 1")) | K10: =IF(I10="","",IF(I10>14,"⚠ Plus de 14 convoqués",""))
A11: =ROW()-3 -> 8 | G11: =IF(B11="","",COUNTIFS(Buts!$A$4:$A$151,A11,Buts!$E$4:$E$151,"Nous")) | H11: =IF(B11="","",COUNTIFS(Buts!$A$4:$A$151,A11,Buts!$E$4:$E$151,"Adverse")) | I11: =IF(B11="","",COUNTIFS('Convocations & Temps de jeu'!$A$4:$A$675,A11,'Convocations & Temps de jeu'!$C$4:$C$675,"Oui")) | J11: =IF(B11="","",COUNTIFS('Convocations & Temps de jeu'!$A$4:$A$675,A11,'Convocations & Temps de jeu'!$C$4:$C$675,"Oui",'Convocations & Temps de jeu'!$G$4:$G$675,"Équipe 1")) | K11: =IF(I11="","",IF(I11>14,"⚠ Plus de 14 convoqués",""))
A12: =ROW()-3 -> 9 | G12: =IF(B12="","",COUNTIFS(Buts!$A$4:$A$151,A12,Buts!$E$4:$E$151,"Nous")) | H12: =IF(B12="","",COUNTIFS(Buts!$A$4:$A$151,A12,Buts!$E$4:$E$151,"Adverse")) | I12: =IF(B12="","",COUNTIFS('Convocations & Temps de jeu'!$A$4:$A$675,A12,'Convocations & Temps de jeu'!$C$4:$C$675,"Oui")) | J12: =IF(B12="","",COUNTIFS('Convocations & Temps de jeu'!$A$4:$A$675,A12,'Convocations & Temps de jeu'!$C$4:$C$675,"Oui",'Convocations & Temps de jeu'!$G$4:$G$675,"Équipe 1")) | K12: =IF(I12="","",IF(I12>14,"⚠ Plus de 14 convoqués",""))
A13: =ROW()-3 -> 10 | G13: =IF(B13="","",COUNTIFS(Buts!$A$4:$A$151,A13,Buts!$E$4:$E$151,"Nous")) | H13: =IF(B13="","",COUNTIFS(Buts!$A$4:$A$151,A13,Buts!$E$4:$E$151,"Adverse")) | I13: =IF(B13="","",COUNTIFS('Convocations & Temps de jeu'!$A$4:$A$675,A13,'Convocations & Temps de jeu'!$C$4:$C$675,"Oui")) | J13: =IF(B13="","",COUNTIFS('Convocations & Temps de jeu'!$A$4:$A$675,A13,'Convocations & Temps de jeu'!$C$4:$C$675,"Oui",'Convocations & Temps de jeu'!$G$4:$G$675,"Équipe 1")) | K13: =IF(I13="","",IF(I13>14,"⚠ Plus de 14 convoqués",""))
A14: =ROW()-3 -> 11 | G14: =IF(B14="","",COUNTIFS(Buts!$A$4:$A$151,A14,Buts!$E$4:$E$151,"Nous")) | H14: =IF(B14="","",COUNTIFS(Buts!$A$4:$A$151,A14,Buts!$E$4:$E$151,"Adverse")) | I14: =IF(B14="","",COUNTIFS('Convocations & Temps de jeu'!$A$4:$A$675,A14,'Convocations & Temps de jeu'!$C$4:$C$675,"Oui")) | J14: =IF(B14="","",COUNTIFS('Convocations & Temps de jeu'!$A$4:$A$675,A14,'Convocations & Temps de jeu'!$C$4:$C$675,"Oui",'Convocations & Temps de jeu'!$G$4:$G$675,"Équipe 1")) | K14: =IF(I14="","",IF(I14>14,"⚠ Plus de 14 convoqués",""))
A15: =ROW()-3 -> 12 | G15: =IF(B15="","",COUNTIFS(Buts!$A$4:$A$151,A15,Buts!$E$4:$E$151,"Nous")) | H15: =IF(B15="","",COUNTIFS(Buts!$A$4:$A$151,A15,Buts!$E$4:$E$151,"Adverse")) | I15: =IF(B15="","",COUNTIFS('Convocations & Temps de jeu'!$A$4:$A$675,A15,'Convocations & Temps de jeu'!$C$4:$C$675,"Oui")) | J15: =IF(B15="","",COUNTIFS('Convocations & Temps de jeu'!$A$4:$A$675,A15,'Convocations & Temps de jeu'!$C$4:$C$675,"Oui",'Convocations & Temps de jeu'!$G$4:$G$675,"Équipe 1")) | K15: =IF(I15="","",IF(I15>14,"⚠ Plus de 14 convoqués",""))
A16: =ROW()-3 -> 13 | G16: =IF(B16="","",COUNTIFS(Buts!$A$4:$A$151,A16,Buts!$E$4:$E$151,"Nous")) | H16: =IF(B16="","",COUNTIFS(Buts!$A$4:$A$151,A16,Buts!$E$4:$E$151,"Adverse")) | I16: =IF(B16="","",COUNTIFS('Convocations & Temps de jeu'!$A$4:$A$675,A16,'Convocations & Temps de jeu'!$C$4:$C$675,"Oui")) | J16: =IF(B16="","",COUNTIFS('Convocations & Temps de jeu'!$A$4:$A$675,A16,'Convocations & Temps de jeu'!$C$4:$C$675,"Oui",'Convocations & Temps de jeu'!$G$4:$G$675,"Équipe 1")) | K16: =IF(I16="","",IF(I16>14,"⚠ Plus de 14 convoqués",""))
A17: =ROW()-3 -> 14 | G17: =IF(B17="","",COUNTIFS(Buts!$A$4:$A$151,A17,Buts!$E$4:$E$151,"Nous")) | H17: =IF(B17="","",COUNTIFS(Buts!$A$4:$A$151,A17,Buts!$E$4:$E$151,"Adverse")) | I17: =IF(B17="","",COUNTIFS('Convocations & Temps de jeu'!$A$4:$A$675,A17,'Convocations & Temps de jeu'!$C$4:$C$675,"Oui")) | J17: =IF(B17="","",COUNTIFS('Convocations & Temps de jeu'!$A$4:$A$675,A17,'Convocations & Temps de jeu'!$C$4:$C$675,"Oui",'Convocations & Temps de jeu'!$G$4:$G$675,"Équipe 1")) | K17: =IF(I17="","",IF(I17>14,"⚠ Plus de 14 convoqués",""))
A18: =ROW()-3 -> 15 | G18: =IF(B18="","",COUNTIFS(Buts!$A$4:$A$151,A18,Buts!$E$4:$E$151,"Nous")) | H18: =IF(B18="","",COUNTIFS(Buts!$A$4:$A$151,A18,Buts!$E$4:$E$151,"Adverse")) | I18: =IF(B18="","",COUNTIFS('Convocations & Temps de jeu'!$A$4:$A$675,A18,'Convocations & Temps de jeu'!$C$4:$C$675,"Oui")) | J18: =IF(B18="","",COUNTIFS('Convocations & Temps de jeu'!$A$4:$A$675,A18,'Convocations & Temps de jeu'!$C$4:$C$675,"Oui",'Convocations & Temps de jeu'!$G$4:$G$675,"Équipe 1")) | K18: =IF(I18="","",IF(I18>14,"⚠ Plus de 14 convoqués",""))
A19: =ROW()-3 -> 16 | G19: =IF(B19="","",COUNTIFS(Buts!$A$4:$A$151,A19,Buts!$E$4:$E$151,"Nous")) | H19: =IF(B19="","",COUNTIFS(Buts!$A$4:$A$151,A19,Buts!$E$4:$E$151,"Adverse")) | I19: =IF(B19="","",COUNTIFS('Convocations & Temps de jeu'!$A$4:$A$675,A19,'Convocations & Temps de jeu'!$C$4:$C$675,"Oui")) | J19: =IF(B19="","",COUNTIFS('Convocations & Temps de jeu'!$A$4:$A$675,A19,'Convocations & Temps de jeu'!$C$4:$C$675,"Oui",'Convocations & Temps de jeu'!$G$4:$G$675,"Équipe 1")) | K19: =IF(I19="","",IF(I19>14,"⚠ Plus de 14 convoqués",""))
... A31: =ROW()-3 -> 28 | G31: =IF(B31="","",COUNTIFS(Buts!$A$4:$A$151,A31,Buts!$E$4:$E$151,"Nous")) | H31: =IF(B31="","",COUNTIFS(Buts!$A$4:$A$151,A31,Buts!$E$4:$E$151,"Adverse")) | I31: =IF(B31="","",COUNTIFS('Convocations & Temps de jeu'!$A$4:$A$675,A31,'Convocations & Temps de jeu'!$C$4:$C$675,"Oui")) | J31: =IF(B31="","",COUNTIFS('Convocations & Temps de jeu'!$A$4:$A$675,A31,'Convocations & Temps de jeu'!$C$4:$C$675,"Oui",'Convocations & Temps de jeu'!$G$4:$G$675,"Équipe 1")) | K31: =IF(I31="","",IF(I31>14,"⚠ Plus de 14 convoqués",""))

Sheet Buts
A1: BUTS ET PASSES DECISIVES
A2: Astuce : choisissez le N° Match et les joueurs dans les listes déroulantes.
A3: N° Match | B3: Minute | C3: Buteur | D3: Passeur décisif | E3: Camp | F3: Type

Sheet Cartons
A1: CARTONS
A2: Astuce : choisissez le N° Match et le joueur dans les listes déroulantes.
A3: N° Match | B3: Minute | C3: Joueur | D3: Équipe | E3: Type | F3: Motif

Sheet Gardien
A1: GARDIEN (suivi buts encaissés / clean sheets)
A2: Astuce : une ligne par match. Si deux gardiens se sont partagé le match, faites une ligne par gardien (le contrôle en colonne G signale un écart avec le score encaissé du match).
A3: N° Match | B3: Gardien | C3: Buts encaissés | D3: Clean sheet | E3: Arrêts (optionnel) | F3: Observations | G3: Contrôle (technique)
D4: =IF(C4="","",IF(C4=0,"Oui","Non")) -> Non | G4: =IF(A4="","",IF(SUMIFS($C$4:$C$500,$A$4:$A$500,A4)=IFERROR(INDEX(Matchs!$H$4:$H$31,MATCH(A4,Matchs!$A$4:$A$31,0)),""),"OK","⚠ Vérifier vs score adverse")) -> OK
D5: =IF(C5="","",IF(C5=0,"Oui","Non")) | G5: =IF(A5="","",IF(SUMIFS($C$4:$C$500,$A$4:$A$500,A5)=IFERROR(INDEX(Matchs!$H$4:$H$31,MATCH(A5,Matchs!$A$4:$A$31,0)),""),"OK","⚠ Vérifier vs score adverse"))
D6: =IF(C6="","",IF(C6=0,"Oui","Non")) | G6: =IF(A6="","",IF(SUMIFS($C$4:$C$500,$A$4:$A$500,A6)=IFERROR(INDEX(Matchs!$H$4:$H$31,MATCH(A6,Matchs!$A$4:$A$31,0)),""),"OK","⚠ Vérifier vs score adverse"))
D7: =IF(C7="","",IF(C7=0,"Oui","Non")) | G7: =IF(A7="","",IF(SUMIFS($C$4:$C$500,$A$4:$A$500,A7)=IFERROR(INDEX(Matchs!$H$4:$H$31,MATCH(A7,Matchs!$A$4:$A$31,0)),""),"OK","⚠ Vérifier vs score adverse"))
D8: =IF(C8="","",IF(C8=0,"Oui","Non")) | G8: =IF(A8="","",IF(SUMIFS($C$4:$C$500,$A$4:$A$500,A8)=IFERROR(INDEX(Matchs!$H$4:$H$31,MATCH(A8,Matchs!$A$4:$A$31,0)),""),"OK","⚠ Vérifier vs score adverse"))
D9: =IF(C9="","",IF(C9=0,"Oui","Non")) | G9: =IF(A9="","",IF(SUMIFS($C$4:$C$500,$A$4:$A$500,A9)=IFERROR(INDEX(Matchs!$H$4:$H$31,MATCH(A9,Matchs!$A$4:$A$31,0)),""),"OK","⚠ Vérifier vs score adverse"))
D10: =IF(C10="","",IF(C10=0,"Oui","Non")) | G10: =IF(A10="","",IF(SUMIFS($C$4:$C$500,$A$4:$A$500,A10)=IFERROR(INDEX(Matchs!$H$4:$H$31,MATCH(A10,Matchs!$A$4:$A$31,0)),""),"OK","⚠ Vérifier vs score adverse"))
D11: =IF(C11="","",IF(C11=0,"Oui","Non")) | G11: =IF(A11="","",IF(SUMIFS($C$4:$C$500,$A$4:$A$500,A11)=IFERROR(INDEX(Matchs!$H$4:$H$31,MATCH(A11,Matchs!$A$4:$A$31,0)),""),"OK","⚠ Vérifier vs score adverse"))
D12: =IF(C12="","",IF(C12=0,"Oui","Non")) | G12: =IF(A12="","",IF(SUMIFS($C$4:$C$500,$A$4:$A$500,A12)=IFERROR(INDEX(Matchs!$H$4:$H$31,MATCH(A12,Matchs!$A$4:$A$31,0)),""),"OK","⚠ Vérifier vs score adverse"))
D13: =IF(C13="","",IF(C13=0,"Oui","Non")) | G13: =IF(A13="","",IF(SUMIFS($C$4:$C$500,$A$4:$A$500,A13)=IFERROR(INDEX(Matchs!$H$4:$H$31,MATCH(A13,Matchs!$A$4:$A$31,0)),""),"OK","⚠ Vérifier vs score adverse"))
D14: =IF(C14="","",IF(C14=0,"Oui","Non")) | G14: =IF(A14="","",IF(SUMIFS($C$4:$C$500,$A$4:$A$500,A14)=IFERROR(INDEX(Matchs!$H$4:$H$31,MATCH(A14,Matchs!$A$4:$A$31,0)),""),"OK","⚠ Vérifier vs score adverse"))
D15: =IF(C15="","",IF(C15=0,"Oui","Non")) | G15: =IF(A15="","",IF(SUMIFS($C$4:$C$500,$A$4:$A$500,A15)=IFERROR(INDEX(Matchs!$H$4:$H$31,MATCH(A15,Matchs!$A$4:$A$31,0)),""),"OK","⚠ Vérifier vs score adverse"))
... D500: =IF(C500="","",IF(C500=0,"Oui","Non")) | G500: =IF(A500="","",IF(SUMIFS($C$4:$C$500,$A$4:$A$500,A500)=IFERROR(INDEX(Matchs!$H$4:$H$31,MATCH(A500,Matchs!$A$4:$A$31,0)),""),"OK","⚠ Vérifier vs score adverse"))

Sheet Changements
A1: CHANGEMENTS (saisie manuelle, à recopier depuis votre feuille de match)
A2: Recopiez ici votre relevé papier tel quel : une ligne par changement (Minute, Joueur sorti, Joueur entré), avec le N° Match. Le temps de jeu de chaque joueur se calcule automatiquement dans l'onglet "Convocations & Temps de jeu", même s'il sort et rentre plusieurs fois.
A3: N° Match | B3: Minute | C3: Joueur sorti | D3: Joueur entré | F3: Ligne sortie (technique) | G3: Clé recherche (technique)

Sheet Convocations & Temps de jeu
A1: CONVOCATIONS ET TEMPS DE JEU (une ligne par passage sur le terrain)
A2: Astuce : les 19 joueurs Équipe 2 sont pré-remplis automatiquement pour chaque match (lignes fixes). Ne saisissez plus aucune minute ici : renseignez chaque changement (Minute, Joueur sorti, Joueur entré) dans l'onglet "Changements" -- le temps de jeu se calcule tout seul, même si un joueur sort et rentre plusieurs fois dans le match. Les 5 lignes libres en bas de chaque bloc servent uniquement aux renforts de l'Équipe 1 (ou à un joueur Équipe 2 en plus si besoin) : choisissez le joueur dans la liste déroulante.
A3: N° Match | B3: Joueur | C3: Convoqué | D3: Motif absence | E3: Titulaire | F3: Contrôle temps de jeu (technique) | G3: Équipe habituelle | H3: Minute d'entrée (info, calculée) | I3: Minute de sortie (info, calculée) | J3: Temps de jeu (min) | K3: Match unique (technique) | L3: Nb entrées (technique) | M3: Nb sorties (technique) | N3: Somme minutes entrée (technique) | O3: Somme minutes sortie (technique) | P3: Convocation unique (technique) | Q3: Titularisation unique (technique)
A4: =INT((ROW()-4)/24)+1 -> 1 | B4: =INDEX('Effectif Saison'!$E$4:$E$22,1) -> Alan MICHON | F4: =IF(B4="","",IF(AND(E4="Oui",COUNTIFS(Changements!$A:$A,A4,Changements!$D:$D,B4)>0),"⚠ Titulaire+entrée ?",IF(ABS(L4-M4)>1,"⚠ vérifier",""))) | G4: =IF(B4="","",IFERROR(INDEX('Effectif Saison'!$D$4:$D$51,MATCH(B4,'Effectif Saison'!$E$4:$E$51,0)),"")) -> Équipe 1 | H4: =IF(L4=0,"",IF(E4="Oui",0,IFERROR(_xlfn.MINIFS(Changements!$B:$B,Changements!$A:$A,A4,Changements!$D:$D,B4),""))) | I4: =IF(M4=0,"",IFERROR(_xlfn.MAXIFS(Changements!$B:$B,Changements!$A:$A,A4,Changements!$C:$C,B4),"")) | J4: =IF(OR(B4="",C4<>"Oui"),"",O4-N4) | K4: =IF(AND(B4<>"",ISNUMBER(J4)),1,0) -> 0 | L4: =IF(B4="",0,COUNTIFS(Changements!$A:$A,A4,Changements!$D:$D,B4)+IF(E4="Oui",1,0)) -> 0 | M4: =IF(B4="",0,COUNTIFS(Changements!$A:$A,A4,Changements!$C:$C,B4)) -> 0 | N4: =IF(B4="",0,SUMIFS(Changements!$B:$B,Changements!$A:$A,A4,Changements!$D:$D,B4)) -> 0 | O4: =IF(B4="",0,SUMIFS(Changements!$B:$B,Changements!$A:$A,A4,Changements!$C:$C,B4)+IF(L4>M4,IFERROR(INDEX(Matchs!$F$4:$F$31,MATCH(A4,Matchs!$A$4:$A$31,0)),0),0)) -> 0 | P4: =IF(AND(B4<>"",C4="Oui"),1,0) -> 0 | Q4: =IF(AND(B4<>"",E4="Oui"),1,0) -> 0
A5: =INT((ROW()-4)/24)+1 -> 1 | B5: =INDEX('Effectif Saison'!$E$4:$E$22,2) -> Jean BRUNTZ | F5: =IF(B5="","",IF(AND(E5="Oui",COUNTIFS(Changements!$A:$A,A5,Changements!$D:$D,B5)>0),"⚠ Titulaire+entrée ?",IF(ABS(L5-M5)>1,"⚠ vérifier",""))) | G5: =IF(B5="","",IFERROR(INDEX('Effectif Saison'!$D$4:$D$51,MATCH(B5,'Effectif Saison'!$E$4:$E$51,0)),"")) -> Équipe 1 | H5: =IF(L5=0,"",IF(E5="Oui",0,IFERROR(_xlfn.MINIFS(Changements!$B:$B,Changements!$A:$A,A5,Changements!$D:$D,B5),""))) | I5: =IF(M5=0,"",IFERROR(_xlfn.MAXIFS(Changements!$B:$B,Changements!$A:$A,A5,Changements!$C:$C,B5),"")) | J5: =IF(OR(B5="",C5<>"Oui"),"",O5-N5) | K5: =IF(AND(B5<>"",ISNUMBER(J5)),1,0) -> 0 | L5: =IF(B5="",0,COUNTIFS(Changements!$A:$A,A5,Changements!$D:$D,B5)+IF(E5="Oui",1,0)) -> 0 | M5: =IF(B5="",0,COUNTIFS(Changements!$A:$A,A5,Changements!$C:$C,B5)) -> 0 | N5: =IF(B5="",0,SUMIFS(Changements!$B:$B,Changements!$A:$A,A5,Changements!$D:$D,B5)) -> 0 | O5: =IF(B5="",0,SUMIFS(Changements!$B:$B,Changements!$A:$A,A5,Changements!$C:$C,B5)+IF(L5>M5,IFERROR(INDEX(Matchs!$F$4:$F$31,MATCH(A5,Matchs!$A$4:$A$31,0)),0),0)) -> 0 | P5: =IF(AND(B5<>"",C5="Oui"),1,0) -> 0 | Q5: =IF(AND(B5<>"",E5="Oui"),1,0) -> 0
A6: =INT((ROW()-4)/24)+1 -> 1 | B6: =INDEX('Effectif Saison'!$E$4:$E$22,3) -> Marouane SBK | F6: =IF(B6="","",IF(AND(E6="Oui",COUNTIFS(Changements!$A:$A,A6,Changements!$D:$D,B6)>0),"⚠ Titulaire+entrée ?",IF(ABS(L6-M6)>1,"⚠ vérifier",""))) | G6: =IF(B6="","",IFERROR(INDEX('Effectif Saison'!$D$4:$D$51,MATCH(B6,'Effectif Saison'!$E$4:$E$51,0)),"")) -> Équipe 1 | H6: =IF(L6=0,"",IF(E6="Oui",0,IFERROR(_xlfn.MINIFS(Changements!$B:$B,Changements!$A:$A,A6,Changements!$D:$D,B6),""))) | I6: =IF(M6=0,"",IFERROR(_xlfn.MAXIFS(Changements!$B:$B,Changements!$A:$A,A6,Changements!$C:$C,B6),"")) | J6: =IF(OR(B6="",C6<>"Oui"),"",O6-N6) | K6: =IF(AND(B6<>"",ISNUMBER(J6)),1,0) -> 0 | L6: =IF(B6="",0,COUNTIFS(Changements!$A:$A,A6,Changements!$D:$D,B6)+IF(E6="Oui",1,0)) -> 0 | M6: =IF(B6="",0,COUNTIFS(Changements!$A:$A,A6,Changements!$C:$C,B6)) -> 0 | N6: =IF(B6="",0,SUMIFS(Changements!$B:$B,Changements!$A:$A,A6,Changements!$D:$D,B6)) -> 0 | O6: =IF(B6="",0,SUMIFS(Changements!$B:$B,Changements!$A:$A,A6,Changements!$C:$C,B6)+IF(L6>M6,IFERROR(INDEX(Matchs!$F$4:$F$31,MATCH(A6,Matchs!$A$4:$A$31,0)),0),0)) -> 0 | P6: =IF(AND(B6<>"",C6="Oui"),1,0) -> 0 | Q6: =IF(AND(B6<>"",E6="Oui"),1,0) -> 0
A7: =INT((ROW()-4)/24)+1 -> 1 | B7: =INDEX('Effectif Saison'!$E$4:$E$22,4) -> Noé BIHL | F7: =IF(B7="","",IF(AND(E7="Oui",COUNTIFS(Changements!$A:$A,A7,Changements!$D:$D,B7)>0),"⚠ Titulaire+entrée ?",IF(ABS(L7-M7)>1,"⚠ vérifier",""))) | G7: =IF(B7="","",IFERROR(INDEX('Effectif Saison'!$D$4:$D$51,MATCH(B7,'Effectif Saison'!$E$4:$E$51,0)),"")) -> Équipe 1 | H7: =IF(L7=0,"",IF(E7="Oui",0,IFERROR(_xlfn.MINIFS(Changements!$B:$B,Changements!$A:$A,A7,Changements!$D:$D,B7),""))) | I7: =IF(M7=0,"",IFERROR(_xlfn.MAXIFS(Changements!$B:$B,Changements!$A:$A,A7,Changements!$C:$C,B7),"")) | J7: =IF(OR(B7="",C7<>"Oui"),"",O7-N7) | K7: =IF(AND(B7<>"",ISNUMBER(J7)),1,0) -> 0 | L7: =IF(B7="",0,COUNTIFS(Changements!$A:$A,A7,Changements!$D:$D,B7)+IF(E7="Oui",1,0)) -> 0 | M7: =IF(B7="",0,COUNTIFS(Changements!$A:$A,A7,Changements!$C:$C,B7)) -> 0 | N7: =IF(B7="",0,SUMIFS(Changements!$B:$B,Changements!$A:$A,A7,Changements!$D:$D,B7)) -> 0 | O7: =IF(B7="",0,SUMIFS(Changements!$B:$B,Changements!$A:$A,A7,Changements!$C:$C,B7)+IF(L7>M7,IFERROR(INDEX(Matchs!$F$4:$F$31,MATCH(A7,Matchs!$A$4:$A$31,0)),0),0)) -> 0 | P7: =IF(AND(B7<>"",C7="Oui"),1,0) -> 0 | Q7: =IF(AND(B7<>"",E7="Oui"),1,0) -> 0
A8: =INT((ROW()-4)/24)+1 -> 1 | B8: =INDEX('Effectif Saison'!$E$4:$E$22,5) -> Luca COLAIANNI | F8: =IF(B8="","",IF(AND(E8="Oui",COUNTIFS(Changements!$A:$A,A8,Changements!$D:$D,B8)>0),"⚠ Titulaire+entrée ?",IF(ABS(L8-M8)>1,"⚠ vérifier",""))) | G8: =IF(B8="","",IFERROR(INDEX('Effectif Saison'!$D$4:$D$51,MATCH(B8,'Effectif Saison'!$E$4:$E$51,0)),"")) -> Équipe 1 | H8: =IF(L8=0,"",IF(E8="Oui",0,IFERROR(_xlfn.MINIFS(Changements!$B:$B,Changements!$A:$A,A8,Changements!$D:$D,B8),""))) | I8: =IF(M8=0,"",IFERROR(_xlfn.MAXIFS(Changements!$B:$B,Changements!$A:$A,A8,Changements!$C:$C,B8),"")) | J8: =IF(OR(B8="",C8<>"Oui"),"",O8-N8) | K8: =IF(AND(B8<>"",ISNUMBER(J8)),1,0) -> 0 | L8: =IF(B8="",0,COUNTIFS(Changements!$A:$A,A8,Changements!$D:$D,B8)+IF(E8="Oui",1,0)) -> 0 | M8: =IF(B8="",0,COUNTIFS(Changements!$A:$A,A8,Changements!$C:$C,B8)) -> 0 | N8: =IF(B8="",0,SUMIFS(Changements!$B:$B,Changements!$A:$A,A8,Changements!$D:$D,B8)) -> 0 | O8: =IF(B8="",0,SUMIFS(Changements!$B:$B,Changements!$A:$A,A8,Changements!$C:$C,B8)+IF(L8>M8,IFERROR(INDEX(Matchs!$F$4:$F$31,MATCH(A8,Matchs!$A$4:$A$31,0)),0),0)) -> 0 | P8: =IF(AND(B8<>"",C8="Oui"),1,0) -> 0 | Q8: =IF(AND(B8<>"",E8="Oui"),1,0) -> 0
A9: =INT((ROW()-4)/24)+1 -> 1 | B9: =INDEX('Effectif Saison'!$E$4:$E$22,6) -> Atilla ER | F9: =IF(B9="","",IF(AND(E9="Oui",COUNTIFS(Changements!$A:$A,A9,Changements!$D:$D,B9)>0),"⚠ Titulaire+entrée ?",IF(ABS(L9-M9)>1,"⚠ vérifier",""))) | G9: =IF(B9="","",IFERROR(INDEX('Effectif Saison'!$D$4:$D$51,MATCH(B9,'Effectif Saison'!$E$4:$E$51,0)),"")) -> Équipe 1 | H9: =IF(L9=0,"",IF(E9="Oui",0,IFERROR(_xlfn.MINIFS(Changements!$B:$B,Changements!$A:$A,A9,Changements!$D:$D,B9),""))) | I9: =IF(M9=0,"",IFERROR(_xlfn.MAXIFS(Changements!$B:$B,Changements!$A:$A,A9,Changements!$C:$C,B9),"")) | J9: =IF(OR(B9="",C9<>"Oui"),"",O9-N9) | K9: =IF(AND(B9<>"",ISNUMBER(J9)),1,0) -> 0 | L9: =IF(B9="",0,COUNTIFS(Changements!$A:$A,A9,Changements!$D:$D,B9)+IF(E9="Oui",1,0)) -> 0 | M9: =IF(B9="",0,COUNTIFS(Changements!$A:$A,A9,Changements!$C:$C,B9)) -> 0 | N9: =IF(B9="",0,SUMIFS(Changements!$B:$B,Changements!$A:$A,A9,Changements!$D:$D,B9)) -> 0 | O9: =IF(B9="",0,SUMIFS(Changements!$B:$B,Changements!$A:$A,A9,Changements!$C:$C,B9)+IF(L9>M9,IFERROR(INDEX(Matchs!$F$4:$F$31,MATCH(A9,Matchs!$A$4:$A$31,0)),0),0)) -> 0 | P9: =IF(AND(B9<>"",C9="Oui"),1,0) -> 0 | Q9: =IF(AND(B9<>"",E9="Oui"),1,0) -> 0
A10: =INT((ROW()-4)/24)+1 -> 1 | B10: =INDEX('Effectif Saison'!$E$4:$E$22,7) -> Lucas BUHR | F10: =IF(B10="","",IF(AND(E10="Oui",COUNTIFS(Changements!$A:$A,A10,Changements!$D:$D,B10)>0),"⚠ Titulaire+entrée ?",IF(ABS(L10-M10)>1,"⚠ vérifier",""))) | G10: =IF(B10="","",IFERROR(INDEX('Effectif Saison'!$D$4:$D$51,MATCH(B10,'Effectif Saison'!$E$4:$E$51,0)),"")) -> Équipe 1 | H10: =IF(L10=0,"",IF(E10="Oui",0,IFERROR(_xlfn.MINIFS(Changements!$B:$B,Changements!$A:$A,A10,Changements!$D:$D,B10),""))) | I10: =IF(M10=0,"",IFERROR(_xlfn.MAXIFS(Changements!$B:$B,Changements!$A:$A,A10,Changements!$C:$C,B10),"")) | J10: =IF(OR(B10="",C10<>"Oui"),"",O10-N10) | K10: =IF(AND(B10<>"",ISNUMBER(J10)),1,0) -> 0 | L10: =IF(B10="",0,COUNTIFS(Changements!$A:$A,A10,Changements!$D:$D,B10)+IF(E10="Oui",1,0)) -> 0 | M10: =IF(B10="",0,COUNTIFS(Changements!$A:$A,A10,Changements!$C:$C,B10)) -> 0 | N10: =IF(B10="",0,SUMIFS(Changements!$B:$B,Changements!$A:$A,A10,Changements!$D:$D,B10)) -> 0 | O10: =IF(B10="",0,SUMIFS(Changements!$B:$B,Changements!$A:$A,A10,Changements!$C:$C,B10)+IF(L10>M10,IFERROR(INDEX(Matchs!$F$4:$F$31,MATCH(A10,Matchs!$A$4:$A$31,0)),0),0)) -> 0 | P10: =IF(AND(B10<>"",C10="Oui"),1,0) -> 0 | Q10: =IF(AND(B10<>"",E10="Oui"),1,0) -> 0
A11: =INT((ROW()-4)/24)+1 -> 1 | B11: =INDEX('Effectif Saison'!$E$4:$E$22,8) -> Yanis HOUX | F11: =IF(B11="","",IF(AND(E11="Oui",COUNTIFS(Changements!$A:$A,A11,Changements!$D:$D,B11)>0),"⚠ Titulaire+entrée ?",IF(ABS(L11-M11)>1,"⚠ vérifier",""))) | G11: =IF(B11="","",IFERROR(INDEX('Effectif Saison'!$D$4:$D$51,MATCH(B11,'Effectif Saison'!$E$4:$E$51,0)),"")) -> Équipe 1 | H11: =IF(L11=0,"",IF(E11="Oui",0,IFERROR(_xlfn.MINIFS(Changements!$B:$B,Changements!$A:$A,A11,Changements!$D:$D,B11),""))) | I11: =IF(M11=0,"",IFERROR(_xlfn.MAXIFS(Changements!$B:$B,Changements!$A:$A,A11,Changements!$C:$C,B11),"")) | J11: =IF(OR(B11="",C11<>"Oui"),"",O11-N11) | K11: =IF(AND(B11<>"",ISNUMBER(J11)),1,0) -> 0 | L11: =IF(B11="",0,COUNTIFS(Changements!$A:$A,A11,Changements!$D:$D,B11)+IF(E11="Oui",1,0)) -> 0 | M11: =IF(B11="",0,COUNTIFS(Changements!$A:$A,A11,Changements!$C:$C,B11)) -> 0 | N11: =IF(B11="",0,SUMIFS(Changements!$B:$B,Changements!$A:$A,A11,Changements!$D:$D,B11)) -> 0 | O11: =IF(B11="",0,SUMIFS(Changements!$B:$B,Changements!$A:$A,A11,Changements!$C:$C,B11)+IF(L11>M11,IFERROR(INDEX(Matchs!$F$4:$F$31,MATCH(A11,Matchs!$A$4:$A$31,0)),0),0)) -> 0 | P11: =IF(AND(B11<>"",C11="Oui"),1,0) -> 0 | Q11: =IF(AND(B11<>"",E11="Oui"),1,0) -> 0
A12: =INT((ROW()-4)/24)+1 -> 1 | B12: =INDEX('Effectif Saison'!$E$4:$E$22,9) -> Tino COLAIANNI | F12: =IF(B12="","",IF(AND(E12="Oui",COUNTIFS(Changements!$A:$A,A12,Changements!$D:$D,B12)>0),"⚠ Titulaire+entrée ?",IF(ABS(L12-M12)>1,"⚠ vérifier",""))) | G12: =IF(B12="","",IFERROR(INDEX('Effectif Saison'!$D$4:$D$51,MATCH(B12,'Effectif Saison'!$E$4:$E$51,0)),"")) -> Équipe 1 | H12: =IF(L12=0,"",IF(E12="Oui",0,IFERROR(_xlfn.MINIFS(Changements!$B:$B,Changements!$A:$A,A12,Changements!$D:$D,B12),""))) | I12: =IF(M12=0,"",IFERROR(_xlfn.MAXIFS(Changements!$B:$B,Changements!$A:$A,A12,Changements!$C:$C,B12),"")) | J12: =IF(OR(B12="",C12<>"Oui"),"",O12-N12) | K12: =IF(AND(B12<>"",ISNUMBER(J12)),1,0) -> 0 | L12: =IF(B12="",0,COUNTIFS(Changements!$A:$A,A12,Changements!$D:$D,B12)+IF(E12="Oui",1,0)) -> 0 | M12: =IF(B12="",0,COUNTIFS(Changements!$A:$A,A12,Changements!$C:$C,B12)) -> 0 | N12: =IF(B12="",0,SUMIFS(Changements!$B:$B,Changements!$A:$A,A12,Changements!$D:$D,B12)) -> 0 | O12: =IF(B12="",0,SUMIFS(Changements!$B:$B,Changements!$A:$A,A12,Changements!$C:$C,B12)+IF(L12>M12,IFERROR(INDEX(Matchs!$F$4:$F$31,MATCH(A12,Matchs!$A$4:$A$31,0)),0),0)) -> 0 | P12: =IF(AND(B12<>"",C12="Oui"),1,0) -> 0 | Q12: =IF(AND(B12<>"",E12="Oui"),1,0) -> 0
A13: =INT((ROW()-4)/24)+1 -> 1 | B13: =INDEX('Effectif Saison'!$E$4:$E$22,10) -> Achille KELLERKNECHT | F13: =IF(B13="","",IF(AND(E13="Oui",COUNTIFS(Changements!$A:$A,A13,Changements!$D:$D,B13)>0),"⚠ Titulaire+entrée ?",IF(ABS(L13-M13)>1,"⚠ vérifier",""))) | G13: =IF(B13="","",IFERROR(INDEX('Effectif Saison'!$D$4:$D$51,MATCH(B13,'Effectif Saison'!$E$4:$E$51,0)),"")) -> Équipe 1 | H13: =IF(L13=0,"",IF(E13="Oui",0,IFERROR(_xlfn.MINIFS(Changements!$B:$B,Changements!$A:$A,A13,Changements!$D:$D,B13),""))) | I13: =IF(M13=0,"",IFERROR(_xlfn.MAXIFS(Changements!$B:$B,Changements!$A:$A,A13,Changements!$C:$C,B13),"")) | J13: =IF(OR(B13="",C13<>"Oui"),"",O13-N13) | K13: =IF(AND(B13<>"",ISNUMBER(J13)),1,0) -> 0 | L13: =IF(B13="",0,COUNTIFS(Changements!$A:$A,A13,Changements!$D:$D,B13)+IF(E13="Oui",1,0)) -> 0 | M13: =IF(B13="",0,COUNTIFS(Changements!$A:$A,A13,Changements!$C:$C,B13)) -> 0 | N13: =IF(B13="",0,SUMIFS(Changements!$B:$B,Changements!$A:$A,A13,Changements!$D:$D,B13)) -> 0 | O13: =IF(B13="",0,SUMIFS(Changements!$B:$B,Changements!$A:$A,A13,Changements!$C:$C,B13)+IF(L13>M13,IFERROR(INDEX(Matchs!$F$4:$F$31,MATCH(A13,Matchs!$A$4:$A$31,0)),0),0)) -> 0 | P13: =IF(AND(B13<>"",C13="Oui"),1,0) -> 0 | Q13: =IF(AND(B13<>"",E13="Oui"),1,0) -> 0
A14: =INT((ROW()-4)/24)+1 -> 1 | B14: =INDEX('Effectif Saison'!$E$4:$E$22,11) -> Charly LEPERT | F14: =IF(B14="","",IF(AND(E14="Oui",COUNTIFS(Changements!$A:$A,A14,Changements!$D:$D,B14)>0),"⚠ Titulaire+entrée ?",IF(ABS(L14-M14)>1,"⚠ vérifier",""))) | G14: =IF(B14="","",IFERROR(INDEX('Effectif Saison'!$D$4:$D$51,MATCH(B14,'Effectif Saison'!$E$4:$E$51,0)),"")) -> Équipe 1 | H14: =IF(L14=0,"",IF(E14="Oui",0,IFERROR(_xlfn.MINIFS(Changements!$B:$B,Changements!$A:$A,A14,Changements!$D:$D,B14),""))) | I14: =IF(M14=0,"",IFERROR(_xlfn.MAXIFS(Changements!$B:$B,Changements!$A:$A,A14,Changements!$C:$C,B14),"")) | J14: =IF(OR(B14="",C14<>"Oui"),"",O14-N14) | K14: =IF(AND(B14<>"",ISNUMBER(J14)),1,0) -> 0 | L14: =IF(B14="",0,COUNTIFS(Changements!$A:$A,A14,Changements!$D:$D,B14)+IF(E14="Oui",1,0)) -> 0 | M14: =IF(B14="",0,COUNTIFS(Changements!$A:$A,A14,Changements!$C:$C,B14)) -> 0 | N14: =IF(B14="",0,SUMIFS(Changements!$B:$B,Changements!$A:$A,A14,Changements!$D:$D,B14)) -> 0 | O14: =IF(B14="",0,SUMIFS(Changements!$B:$B,Changements!$A:$A,A14,Changements!$C:$C,B14)+IF(L14>M14,IFERROR(INDEX(Matchs!$F$4:$F$31,MATCH(A14,Matchs!$A$4:$A$31,0)),0),0)) -> 0 | P14: =IF(AND(B14<>"",C14="Oui"),1,0) -> 0 | Q14: =IF(AND(B14<>"",E14="Oui"),1,0) -> 0
A15: =INT((ROW()-4)/24)+1 -> 1 | B15: =INDEX('Effectif Saison'!$E$4:$E$22,12) -> Basile STANGRET | F15: =IF(B15="","",IF(AND(E15="Oui",COUNTIFS(Changements!$A:$A,A15,Changements!$D:$D,B15)>0),"⚠ Titulaire+entrée ?",IF(ABS(L15-M15)>1,"⚠ vérifier",""))) | G15: =IF(B15="","",IFERROR(INDEX('Effectif Saison'!$D$4:$D$51,MATCH(B15,'Effectif Saison'!$E$4:$E$51,0)),"")) -> Équipe 1 | H15: =IF(L15=0,"",IF(E15="Oui",0,IFERROR(_xlfn.MINIFS(Changements!$B:$B,Changements!$A:$A,A15,Changements!$D:$D,B15),""))) | I15: =IF(M15=0,"",IFERROR(_xlfn.MAXIFS(Changements!$B:$B,Changements!$A:$A,A15,Changements!$C:$C,B15),"")) | J15: =IF(OR(B15="",C15<>"Oui"),"",O15-N15) | K15: =IF(AND(B15<>"",ISNUMBER(J15)),1,0) -> 0 | L15: =IF(B15="",0,COUNTIFS(Changements!$A:$A,A15,Changements!$D:$D,B15)+IF(E15="Oui",1,0)) -> 0 | M15: =IF(B15="",0,COUNTIFS(Changements!$A:$A,A15,Changements!$C:$C,B15)) -> 0 | N15: =IF(B15="",0,SUMIFS(Changements!$B:$B,Changements!$A:$A,A15,Changements!$D:$D,B15)) -> 0 | O15: =IF(B15="",0,SUMIFS(Changements!$B:$B,Changements!$A:$A,A15,Changements!$C:$C,B15)+IF(L15>M15,IFERROR(INDEX(Matchs!$F$4:$F$31,MATCH(A15,Matchs!$A$4:$A$31,0)),0),0)) -> 0 | P15: =IF(AND(B15<>"",C15="Oui"),1,0) -> 0 | Q15: =IF(AND(B15<>"",E15="Oui"),1,0) -> 0
A16: =INT((ROW()-4)/24)+1 -> 1 | B16: =INDEX('Effectif Saison'!$E$4:$E$22,13) -> Maxence KELLER | F16: =IF(B16="","",IF(AND(E16="Oui",COUNTIFS(Changements!$A:$A,A16,Changements!$D:$D,B16)>0),"⚠ Titulaire+entrée ?",IF(ABS(L16-M16)>1,"⚠ vérifier",""))) | G16: =IF(B16="","",IFERROR(INDEX('Effectif Saison'!$D$4:$D$51,MATCH(B16,'Effectif Saison'!$E$4:$E$51,0)),"")) -> Équipe 1 | H16: =IF(L16=0,"",IF(E16="Oui",0,IFERROR(_xlfn.MINIFS(Changements!$B:$B,Changements!$A:$A,A16,Changements!$D:$D,B16),""))) | I16: =IF(M16=0,"",IFERROR(_xlfn.MAXIFS(Changements!$B:$B,Changements!$A:$A,A16,Changements!$C:$C,B16),"")) | J16: =IF(OR(B16="",C16<>"Oui"),"",O16-N16) | K16: =IF(AND(B16<>"",ISNUMBER(J16)),1,0) -> 0 | L16: =IF(B16="",0,COUNTIFS(Changements!$A:$A,A16,Changements!$D:$D,B16)+IF(E16="Oui",1,0)) -> 0 | M16: =IF(B16="",0,COUNTIFS(Changements!$A:$A,A16,Changements!$C:$C,B16)) -> 0 | N16: =IF(B16="",0,SUMIFS(Changements!$B:$B,Changements!$A:$A,A16,Changements!$D:$D,B16)) -> 0 | O16: =IF(B16="",0,SUMIFS(Changements!$B:$B,Changements!$A:$A,A16,Changements!$C:$C,B16)+IF(L16>M16,IFERROR(INDEX(Matchs!$F$4:$F$31,MATCH(A16,Matchs!$A$4:$A$31,0)),0),0)) -> 0 | P16: =IF(AND(B16<>"",C16="Oui"),1,0) -> 0 | Q16: =IF(AND(B16<>"",E16="Oui"),1,0) -> 0
A17: =INT((ROW()-4)/24)+1 -> 1 | B17: =INDEX('Effectif Saison'!$E$4:$E$22,14) -> Evan SCHMITT | F17: =IF(B17="","",IF(AND(E17="Oui",COUNTIFS(Changements!$A:$A,A17,Changements!$D:$D,B17)>0),"⚠ Titulaire+entrée ?",IF(ABS(L17-M17)>1,"⚠ vérifier",""))) | G17: =IF(B17="","",IFERROR(INDEX('Effectif Saison'!$D$4:$D$51,MATCH(B17,'Effectif Saison'!$E$4:$E$51,0)),"")) -> Équipe 1 | H17: =IF(L17=0,"",IF(E17="Oui",0,IFERROR(_xlfn.MINIFS(Changements!$B:$B,Changements!$A:$A,A17,Changements!$D:$D,B17),""))) | I17: =IF(M17=0,"",IFERROR(_xlfn.MAXIFS(Changements!$B:$B,Changements!$A:$A,A17,Changements!$C:$C,B17),"")) | J17: =IF(OR(B17="",C17<>"Oui"),"",O17-N17) | K17: =IF(AND(B17<>"",ISNUMBER(J17)),1,0) -> 0 | L17: =IF(B17="",0,COUNTIFS(Changements!$A:$A,A17,Changements!$D:$D,B17)+IF(E17="Oui",1,0)) -> 0 | M17: =IF(B17="",0,COUNTIFS(Changements!$A:$A,A17,Changements!$C:$C,B17)) -> 0 | N17: =IF(B17="",0,SUMIFS(Changements!$B:$B,Changements!$A:$A,A17,Changements!$D:$D,B17)) -> 0 | O17: =IF(B17="",0,SUMIFS(Changements!$B:$B,Changements!$A:$A,A17,Changements!$C:$C,B17)+IF(L17>M17,IFERROR(INDEX(Matchs!$F$4:$F$31,MATCH(A17,Matchs!$A$4:$A$31,0)),0),0)) -> 0 | P17: =IF(AND(B17<>"",C17="Oui"),1,0) -> 0 | Q17: =IF(AND(B17<>"",E17="Oui"),1,0) -> 0
A18: =INT((ROW()-4)/24)+1 -> 1 | B18: =INDEX('Effectif Saison'!$E$4:$E$22,15) -> William SIMON | F18: =IF(B18="","",IF(AND(E18="Oui",COUNTIFS(Changements!$A:$A,A18,Changements!$D:$D,B18)>0),"⚠ Titulaire+entrée ?",IF(ABS(L18-M18)>1,"⚠ vérifier",""))) | G18: =IF(B18="","",IFERROR(INDEX('Effectif Saison'!$D$4:$D$51,MATCH(B18,'Effectif Saison'!$E$4:$E$51,0)),"")) -> Équipe 1 | H18: =IF(L18=0,"",IF(E18="Oui",0,IFERROR(_xlfn.MINIFS(Changements!$B:$B,Changements!$A:$A,A18,Changements!$D:$D,B18),""))) | I18: =IF(M18=0,"",IFERROR(_xlfn.MAXIFS(Changements!$B:$B,Changements!$A:$A,A18,Changements!$C:$C,B18),"")) | J18: =IF(OR(B18="",C18<>"Oui"),"",O18-N18) | K18: =IF(AND(B18<>"",ISNUMBER(J18)),1,0) -> 0 | L18: =IF(B18="",0,COUNTIFS(Changements!$A:$A,A18,Changements!$D:$D,B18)+IF(E18="Oui",1,0)) -> 0 | M18: =IF(B18="",0,COUNTIFS(Changements!$A:$A,A18,Changements!$C:$C,B18)) -> 0 | N18: =IF(B18="",0,SUMIFS(Changements!$B:$B,Changements!$A:$A,A18,Changements!$D:$D,B18)) -> 0 | O18: =IF(B18="",0,SUMIFS(Changements!$B:$B,Changements!$A:$A,A18,Changements!$C:$C,B18)+IF(L18>M18,IFERROR(INDEX(Matchs!$F$4:$F$31,MATCH(A18,Matchs!$A$4:$A$31,0)),0),0)) -> 0 | P18: =IF(AND(B18<>"",C18="Oui"),1,0) -> 0 | Q18: =IF(AND(B18<>"",E18="Oui"),1,0) -> 0
A19: =INT((ROW()-4)/24)+1 -> 1 | B19: =INDEX('Effectif Saison'!$E$4:$E$22,16) -> Lenny LEPPER | F19: =IF(B19="","",IF(AND(E19="Oui",COUNTIFS(Changements!$A:$A,A19,Changements!$D:$D,B19)>0),"⚠ Titulaire+entrée ?",IF(ABS(L19-M19)>1,"⚠ vérifier",""))) | G19: =IF(B19="","",IFERROR(INDEX('Effectif Saison'!$D$4:$D$51,MATCH(B19,'Effectif Saison'!$E$4:$E$51,0)),"")) -> Équipe 1 | H19: =IF(L19=0,"",IF(E19="Oui",0,IFERROR(_xlfn.MINIFS(Changements!$B:$B,Changements!$A:$A,A19,Changements!$D:$D,B19),""))) | I19: =IF(M19=0,"",IFERROR(_xlfn.MAXIFS(Changements!$B:$B,Changements!$A:$A,A19,Changements!$C:$C,B19),"")) | J19: =IF(OR(B19="",C19<>"Oui"),"",O19-N19) | K19: =IF(AND(B19<>"",ISNUMBER(J19)),1,0) -> 0 | L19: =IF(B19="",0,COUNTIFS(Changements!$A:$A,A19,Changements!$D:$D,B19)+IF(E19="Oui",1,0)) -> 0 | M19: =IF(B19="",0,COUNTIFS(Changements!$A:$A,A19,Changements!$C:$C,B19)) -> 0 | N19: =IF(B19="",0,SUMIFS(Changements!$B:$B,Changements!$A:$A,A19,Changements!$D:$D,B19)) -> 0 | O19: =IF(B19="",0,SUMIFS(Changements!$B:$B,Changements!$A:$A,A19,Changements!$C:$C,B19)+IF(L19>M19,IFERROR(INDEX(Matchs!$F$4:$F$31,MATCH(A19,Matchs!$A$4:$A$31,0)),0),0)) -> 0 | P19: =IF(AND(B19<>"",C19="Oui"),1,0) -> 0 | Q19: =IF(AND(B19<>"",E19="Oui"),1,0) -> 0
A20: =INT((ROW()-4)/24)+1 -> 1 | B20: =INDEX('Effectif Saison'!$E$4:$E$22,17) -> Malo KELLER | F20: =IF(B20="","",IF(AND(E20="Oui",COUNTIFS(Changements!$A:$A,A20,Changements!$D:$D,B20)>0),"⚠ Titulaire+entrée ?",IF(ABS(L20-M20)>1,"⚠ vérifier",""))) | G20: =IF(B20="","",IFERROR(INDEX('Effectif Saison'!$D$4:$D$51,MATCH(B20,'Effectif Saison'!$E$4:$E$51,0)),"")) -> Équipe 1 | H20: =IF(L20=0,"",IF(E20="Oui",0,IFERROR(_xlfn.MINIFS(Changements!$B:$B,Changements!$A:$A,A20,Changements!$D:$D,B20),""))) | I20: =IF(M20=0,"",IFERROR(_xlfn.MAXIFS(Changements!$B:$B,Changements!$A:$A,A20,Changements!$C:$C,B20),"")) | J20: =IF(OR(B20="",C20<>"Oui"),"",O20-N20) | K20: =IF(AND(B20<>"",ISNUMBER(J20)),1,0) -> 0 | L20: =IF(B20="",0,COUNTIFS(Changements!$A:$A,A20,Changements!$D:$D,B20)+IF(E20="Oui",1,0)) -> 0 | M20: =IF(B20="",0,COUNTIFS(Changements!$A:$A,A20,Changements!$C:$C,B20)) -> 0 | N20: =IF(B20="",0,SUMIFS(Changements!$B:$B,Changements!$A:$A,A20,Changements!$D:$D,B20)) -> 0 | O20: =IF(B20="",0,SUMIFS(Changements!$B:$B,Changements!$A:$A,A20,Changements!$C:$C,B20)+IF(L20>M20,IFERROR(INDEX(Matchs!$F$4:$F$31,MATCH(A20,Matchs!$A$4:$A$31,0)),0),0)) -> 0 | P20: =IF(AND(B20<>"",C20="Oui"),1,0) -> 0 | Q20: =IF(AND(B20<>"",E20="Oui"),1,0) -> 0
A21: =INT((ROW()-4)/24)+1 -> 1 | B21: =INDEX('Effectif Saison'!$E$4:$E$22,18) -> Tom SCHILLER | F21: =IF(B21="","",IF(AND(E21="Oui",COUNTIFS(Changements!$A:$A,A21,Changements!$D:$D,B21)>0),"⚠ Titulaire+entrée ?",IF(ABS(L21-M21)>1,"⚠ vérifier",""))) | G21: =IF(B21="","",IFERROR(INDEX('Effectif Saison'!$D$4:$D$51,MATCH(B21,'Effectif Saison'!$E$4:$E$51,0)),"")) -> Équipe 1 | H21: =IF(L21=0,"",IF(E21="Oui",0,IFERROR(_xlfn.MINIFS(Changements!$B:$B,Changements!$A:$A,A21,Changements!$D:$D,B21),""))) | I21: =IF(M21=0,"",IFERROR(_xlfn.MAXIFS(Changements!$B:$B,Changements!$A:$A,A21,Changements!$C:$C,B21),"")) | J21: =IF(OR(B21="",C21<>"Oui"),"",O21-N21) | K21: =IF(AND(B21<>"",ISNUMBER(J21)),1,0) -> 0 | L21: =IF(B21="",0,COUNTIFS(Changements!$A:$A,A21,Changements!$D:$D,B21)+IF(E21="Oui",1,0)) -> 0 | M21: =IF(B21="",0,COUNTIFS(Changements!$A:$A,A21,Changements!$C:$C,B21)) -> 0 | N21: =IF(B21="",0,SUMIFS(Changements!$B:$B,Changements!$A:$A,A21,Changements!$D:$D,B21)) -> 0 | O21: =IF(B21="",0,SUMIFS(Changements!$B:$B,Changements!$A:$A,A21,Changements!$C:$C,B21)+IF(L21>M21,IFERROR(INDEX(Matchs!$F$4:$F$31,MATCH(A21,Matchs!$A$4:$A$31,0)),0),0)) -> 0 | P21: =IF(AND(B21<>"",C21="Oui"),1,0) -> 0 | Q21: =IF(AND(B21<>"",E21="Oui"),1,0) -> 0
A22: =INT((ROW()-4)/24)+1 -> 1 | B22: =INDEX('Effectif Saison'!$E$4:$E$22,19) -> Eliot LEIBY | F22: =IF(B22="","",IF(AND(E22="Oui",COUNTIFS(Changements!$A:$A,A22,Changements!$D:$D,B22)>0),"⚠ Titulaire+entrée ?",IF(ABS(L22-M22)>1,"⚠ vérifier",""))) | G22: =IF(B22="","",IFERROR(INDEX('Effectif Saison'!$D$4:$D$51,MATCH(B22,'Effectif Saison'!$E$4:$E$51,0)),"")) -> Équipe 1 | H22: =IF(L22=0,"",IF(E22="Oui",0,IFERROR(_xlfn.MINIFS(Changements!$B:$B,Changements!$A:$A,A22,Changements!$D:$D,B22),""))) | I22: =IF(M22=0,"",IFERROR(_xlfn.MAXIFS(Changements!$B:$B,Changements!$A:$A,A22,Changements!$C:$C,B22),"")) | J22: =IF(OR(B22="",C22<>"Oui"),"",O22-N22) | K22: =IF(AND(B22<>"",ISNUMBER(J22)),1,0) -> 0 | L22: =IF(B22="",0,COUNTIFS(Changements!$A:$A,A22,Changements!$D:$D,B22)+IF(E22="Oui",1,0)) -> 0 | M22: =IF(B22="",0,COUNTIFS(Changements!$A:$A,A22,Changements!$C:$C,B22)) -> 0 | N22: =IF(B22="",0,SUMIFS(Changements!$B:$B,Changements!$A:$A,A22,Changements!$D:$D,B22)) -> 0 | O22: =IF(B22="",0,SUMIFS(Changements!$B:$B,Changements!$A:$A,A22,Changements!$C:$C,B22)+IF(L22>M22,IFERROR(INDEX(Matchs!$F$4:$F$31,MATCH(A22,Matchs!$A$4:$A$31,0)),0),0)) -> 0 | P22: =IF(AND(B22<>"",C22="Oui"),1,0) -> 0 | Q22: =IF(AND(B22<>"",E22="Oui"),1,0) -> 0
A23: =INT((ROW()-4)/24)+1 -> 1 | F23: =IF(B23="","",IF(AND(E23="Oui",COUNTIFS(Changements!$A:$A,A23,Changements!$D:$D,B23)>0),"⚠ Titulaire+entrée ?",IF(ABS(L23-M23)>1,"⚠ vérifier",""))) | G23: =IF(B23="","",IFERROR(INDEX('Effectif Saison'!$D$4:$D$51,MATCH(B23,'Effectif Saison'!$E$4:$E$51,0)),"")) | H23: =IF(L23=0,"",IF(E23="Oui",0,IFERROR(_xlfn.MINIFS(Changements!$B:$B,Changements!$A:$A,A23,Changements!$D:$D,B23),""))) | I23: =IF(M23=0,"",IFERROR(_xlfn.MAXIFS(Changements!$B:$B,Changements!$A:$A,A23,Changements!$C:$C,B23),"")) | J23: =IF(OR(B23="",C23<>"Oui"),"",O23-N23) | K23: =IF(AND(B23<>"",ISNUMBER(J23)),1,0) -> 0 | L23: =IF(B23="",0,COUNTIFS(Changements!$A:$A,A23,Changements!$D:$D,B23)+IF(E23="Oui",1,0)) -> 0 | M23: =IF(B23="",0,COUNTIFS(Changements!$A:$A,A23,Changements!$C:$C,B23)) -> 0 | N23: =IF(B23="",0,SUMIFS(Changements!$B:$B,Changements!$A:$A,A23,Changements!$D:$D,B23)) -> 0 | O23: =IF(B23="",0,SUMIFS(Changements!$B:$B,Changements!$A:$A,A23,Changements!$C:$C,B23)+IF(L23>M23,IFERROR(INDEX(Matchs!$F$4:$F$31,MATCH(A23,Matchs!$A$4:$A$31,0)),0),0)) -> 0 | P23: =IF(AND(B23<>"",C23="Oui"),1,0) -> 0 | Q23: =IF(AND(B23<>"",E23="Oui"),1,0) -> 0
A24: =INT((ROW()-4)/24)+1 -> 1 | F24: =IF(B24="","",IF(AND(E24="Oui",COUNTIFS(Changements!$A:$A,A24,Changements!$D:$D,B24)>0),"⚠ Titulaire+entrée ?",IF(ABS(L24-M24)>1,"⚠ vérifier",""))) | G24: =IF(B24="","",IFERROR(INDEX('Effectif Saison'!$D$4:$D$51,MATCH(B24,'Effectif Saison'!$E$4:$E$51,0)),"")) | H24: =IF(L24=0,"",IF(E24="Oui",0,IFERROR(_xlfn.MINIFS(Changements!$B:$B,Changements!$A:$A,A24,Changements!$D:$D,B24),""))) | I24: =IF(M24=0,"",IFERROR(_xlfn.MAXIFS(Changements!$B:$B,Changements!$A:$A,A24,Changements!$C:$C,B24),"")) | J24: =IF(OR(B24="",C24<>"Oui"),"",O24-N24) | K24: =IF(AND(B24<>"",ISNUMBER(J24)),1,0) -> 0 | L24: =IF(B24="",0,COUNTIFS(Changements!$A:$A,A24,Changements!$D:$D,B24)+IF(E24="Oui",1,0)) -> 0 | M24: =IF(B24="",0,COUNTIFS(Changements!$A:$A,A24,Changements!$C:$C,B24)) -> 0 | N24: =IF(B24="",0,SUMIFS(Changements!$B:$B,Changements!$A:$A,A24,Changements!$D:$D,B24)) -> 0 | O24: =IF(B24="",0,SUMIFS(Changements!$B:$B,Changements!$A:$A,A24,Changements!$C:$C,B24)+IF(L24>M24,IFERROR(INDEX(Matchs!$F$4:$F$31,MATCH(A24,Matchs!$A$4:$A$31,0)),0),0)) -> 0 | P24: =IF(AND(B24<>"",C24="Oui"),1,0) -> 0 | Q24: =IF(AND(B24<>"",E24="Oui"),1,0) -> 0
A25: =INT((ROW()-4)/24)+1 -> 1 | F25: =IF(B25="","",IF(AND(E25="Oui",COUNTIFS(Changements!$A:$A,A25,Changements!$D:$D,B25)>0),"⚠ Titulaire+entrée ?",IF(ABS(L25-M25)>1,"⚠ vérifier",""))) | G25: =IF(B25="","",IFERROR(INDEX('Effectif Saison'!$D$4:$D$51,MATCH(B25,'Effectif Saison'!$E$4:$E$51,0)),"")) | H25: =IF(L25=0,"",IF(E25="Oui",0,IFERROR(_xlfn.MINIFS(Changements!$B:$B,Changements!$A:$A,A25,Changements!$D:$D,B25),""))) | I25: =IF(M25=0,"",IFERROR(_xlfn.MAXIFS(Changements!$B:$B,Changements!$A:$A,A25,Changements!$C:$C,B25),"")) | J25: =IF(OR(B25="",C25<>"Oui"),"",O25-N25) | K25: =IF(AND(B25<>"",ISNUMBER(J25)),1,0) -> 0 | L25: =IF(B25="",0,COUNTIFS(Changements!$A:$A,A25,Changements!$D:$D,B25)+IF(E25="Oui",1,0)) -> 0 | M25: =IF(B25="",0,COUNTIFS(Changements!$A:$A,A25,Changements!$C:$C,B25)) -> 0 | N25: =IF(B25="",0,SUMIFS(Changements!$B:$B,Changements!$A:$A,A25,Changements!$D:$D,B25)) -> 0 | O25: =IF(B25="",0,SUMIFS(Changements!$B:$B,Changements!$A:$A,A25,Changements!$C:$C,B25)+IF(L25>M25,IFERROR(INDEX(Matchs!$F$4:$F$31,MATCH(A25,Matchs!$A$4:$A$31,0)),0),0)) -> 0 | P25: =IF(AND(B25<>"",C25="Oui"),1,0) -> 0 | Q25: =IF(AND(B25<>"",E25="Oui"),1,0) -> 0
A26: =INT((ROW()-4)/24)+1 -> 1 | F26: =IF(B26="","",IF(AND(E26="Oui",COUNTIFS(Changements!$A:$A,A26,Changements!$D:$D,B26)>0),"⚠ Titulaire+entrée ?",IF(ABS(L26-M26)>1,"⚠ vérifier",""))) | G26: =IF(B26="","",IFERROR(INDEX('Effectif Saison'!$D$4:$D$51,MATCH(B26,'Effectif Saison'!$E$4:$E$51,0)),"")) | H26: =IF(L26=0,"",IF(E26="Oui",0,IFERROR(_xlfn.MINIFS(Changements!$B:$B,Changements!$A:$A,A26,Changements!$D:$D,B26),""))) | I26: =IF(M26=0,"",IFERROR(_xlfn.MAXIFS(Changements!$B:$B,Changements!$A:$A,A26,Changements!$C:$C,B26),"")) | J26: =IF(OR(B26="",C26<>"Oui"),"",O26-N26) | K26: =IF(AND(B26<>"",ISNUMBER(J26)),1,0) -> 0 | L26: =IF(B26="",0,COUNTIFS(Changements!$A:$A,A26,Changements!$D:$D,B26)+IF(E26="Oui",1,0)) -> 0 | M26: =IF(B26="",0,COUNTIFS(Changements!$A:$A,A26,Changements!$C:$C,B26)) -> 0 | N26: =IF(B26="",0,SUMIFS(Changements!$B:$B,Changements!$A:$A,A26,Changements!$D:$D,B26)) -> 0 | O26: =IF(B26="",0,SUMIFS(Changements!$B:$B,Changements!$A:$A,A26,Changements!$C:$C,B26)+IF(L26>M26,IFERROR(INDEX(Matchs!$F$4:$F$31,MATCH(A26,Matchs!$A$4:$A$31,0)),0),0)) -> 0 | P26: =IF(AND(B26<>"",C26="Oui"),1,0) -> 0 | Q26: =IF(AND(B26<>"",E26="Oui"),1,0) -> 0
A27: =INT((ROW()-4)/24)+1 -> 1 | F27: =IF(B27="","",IF(AND(E27="Oui",COUNTIFS(Changements!$A:$A,A27,Changements!$D:$D,B27)>0),"⚠ Titulaire+entrée ?",IF(ABS(L27-M27)>1,"⚠ vérifier",""))) | G27: =IF(B27="","",IFERROR(INDEX('Effectif Saison'!$D$4:$D$51,MATCH(B27,'Effectif Saison'!$E$4:$E$51,0)),"")) | H27: =IF(L27=0,"",IF(E27="Oui",0,IFERROR(_xlfn.MINIFS(Changements!$B:$B,Changements!$A:$A,A27,Changements!$D:$D,B27),""))) | I27: =IF(M27=0,"",IFERROR(_xlfn.MAXIFS(Changements!$B:$B,Changements!$A:$A,A27,Changements!$C:$C,B27),"")) | J27: =IF(OR(B27="",C27<>"Oui"),"",O27-N27) | K27: =IF(AND(B27<>"",ISNUMBER(J27)),1,0) -> 0 | L27: =IF(B27="",0,COUNTIFS(Changements!$A:$A,A27,Changements!$D:$D,B27)+IF(E27="Oui",1,0)) -> 0 | M27: =IF(B27="",0,COUNTIFS(Changements!$A:$A,A27,Changements!$C:$C,B27)) -> 0 | N27: =IF(B27="",0,SUMIFS(Changements!$B:$B,Changements!$A:$A,A27,Changements!$D:$D,B27)) -> 0 | O27: =IF(B27="",0,SUMIFS(Changements!$B:$B,Changements!$A:$A,A27,Changements!$C:$C,B27)+IF(L27>M27,IFERROR(INDEX(Matchs!$F$4:$F$31,MATCH(A27,Matchs!$A$4:$A$31,0)),0),0)) -> 0 | P27: =IF(AND(B27<>"",C27="Oui"),1,0) -> 0 | Q27: =IF(AND(B27<>"",E27="Oui"),1,0) -> 0
A28: =INT((ROW()-4)/24)+1 -> 2 | B28: =INDEX('Effectif Saison'!$E$4:$E$22,1) -> Alan MICHON | F28: =IF(B28="","",IF(AND(E28="Oui",COUNTIFS(Changements!$A:$A,A28,Changements!$D:$D,B28)>0),"⚠ Titulaire+entrée ?",IF(ABS(L28-M28)>1,"⚠ vérifier",""))) | G28: =IF(B28="","",IFERROR(INDEX('Effectif Saison'!$D$4:$D$51,MATCH(B28,'Effectif Saison'!$E$4:$E$51,0)),"")) -> Équipe 1 | H28: =IF(L28=0,"",IF(E28="Oui",0,IFERROR(_xlfn.MINIFS(Changements!$B:$B,Changements!$A:$A,A28,Changements!$D:$D,B28),""))) | I28: =IF(M28=0,"",IFERROR(_xlfn.MAXIFS(Changements!$B:$B,Changements!$A:$A,A28,Changements!$C:$C,B28),"")) | J28: =IF(OR(B28="",C28<>"Oui"),"",O28-N28) | K28: =IF(AND(B28<>"",ISNUMBER(J28)),1,0) -> 0 | L28: =IF(B28="",0,COUNTIFS(Changements!$A:$A,A28,Changements!$D:$D,B28)+IF(E28="Oui",1,0)) -> 0 | M28: =IF(B28="",0,COUNTIFS(Changements!$A:$A,A28,Changements!$C:$C,B28)) -> 0 | N28: =IF(B28="",0,SUMIFS(Changements!$B:$B,Changements!$A:$A,A28,Changements!$D:$D,B28)) -> 0 | O28: =IF(B28="",0,SUMIFS(Changements!$B:$B,Changements!$A:$A,A28,Changements!$C:$C,B28)+IF(L28>M28,IFERROR(INDEX(Matchs!$F$4:$F$31,MATCH(A28,Matchs!$A$4:$A$31,0)),0),0)) -> 0 | P28: =IF(AND(B28<>"",C28="Oui"),1,0) -> 0 | Q28: =IF(AND(B28<>"",E28="Oui"),1,0) -> 0
A29: =INT((ROW()-4)/24)+1 -> 2 | B29: =INDEX('Effectif Saison'!$E$4:$E$22,2) -> Jean BRUNTZ | F29: =IF(B29="","",IF(AND(E29="Oui",COUNTIFS(Changements!$A:$A,A29,Changements!$D:$D,B29)>0),"⚠ Titulaire+entrée ?",IF(ABS(L29-M29)>1,"⚠ vérifier",""))) | G29: =IF(B29="","",IFERROR(INDEX('Effectif Saison'!$D$4:$D$51,MATCH(B29,'Effectif Saison'!$E$4:$E$51,0)),"")) -> Équipe 1 | H29: =IF(L29=0,"",IF(E29="Oui",0,IFERROR(_xlfn.MINIFS(Changements!$B:$B,Changements!$A:$A,A29,Changements!$D:$D,B29),""))) | I29: =IF(M29=0,"",IFERROR(_xlfn.MAXIFS(Changements!$B:$B,Changements!$A:$A,A29,Changements!$C:$C,B29),"")) | J29: =IF(OR(B29="",C29<>"Oui"),"",O29-N29) | K29: =IF(AND(B29<>"",ISNUMBER(J29)),1,0) -> 0 | L29: =IF(B29="",0,COUNTIFS(Changements!$A:$A,A29,Changements!$D:$D,B29)+IF(E29="Oui",1,0)) -> 0 | M29: =IF(B29="",0,COUNTIFS(Changements!$A:$A,A29,Changements!$C:$C,B29)) -> 0 | N29: =IF(B29="",0,SUMIFS(Changements!$B:$B,Changements!$A:$A,A29,Changements!$D:$D,B29)) -> 0 | O29: =IF(B29="",0,SUMIFS(Changements!$B:$B,Changements!$A:$A,A29,Changements!$C:$C,B29)+IF(L29>M29,IFERROR(INDEX(Matchs!$F$4:$F$31,MATCH(A29,Matchs!$A$4:$A$31,0)),0),0)) -> 0 | P29: =IF(AND(B29<>"",C29="Oui"),1,0) -> 0 | Q29: =IF(AND(B29<>"",E29="Oui"),1,0) -> 0
A30: =INT((ROW()-4)/24)+1 -> 2 | B30: =INDEX('Effectif Saison'!$E$4:$E$22,3) -> Marouane SBK | F30: =IF(B30="","",IF(AND(E30="Oui",COUNTIFS(Changements!$A:$A,A30,Changements!$D:$D,B30)>0),"⚠ Titulaire+entrée ?",IF(ABS(L30-M30)>1,"⚠ vérifier",""))) | G30: =IF(B30="","",IFERROR(INDEX('Effectif Saison'!$D$4:$D$51,MATCH(B30,'Effectif Saison'!$E$4:$E$51,0)),"")) -> Équipe 1 | H30: =IF(L30=0,"",IF(E30="Oui",0,IFERROR(_xlfn.MINIFS(Changements!$B:$B,Changements!$A:$A,A30,Changements!$D:$D,B30),""))) | I30: =IF(M30=0,"",IFERROR(_xlfn.MAXIFS(Changements!$B:$B,Changements!$A:$A,A30,Changements!$C:$C,B30),"")) | J30: =IF(OR(B30="",C30<>"Oui"),"",O30-N30) | K30: =IF(AND(B30<>"",ISNUMBER(J30)),1,0) -> 0 | L30: =IF(B30="",0,COUNTIFS(Changements!$A:$A,A30,Changements!$D:$D,B30)+IF(E30="Oui",1,0)) -> 0 | M30: =IF(B30="",0,COUNTIFS(Changements!$A:$A,A30,Changements!$C:$C,B30)) -> 0 | N30: =IF(B30="",0,SUMIFS(Changements!$B:$B,Changements!$A:$A,A30,Changements!$D:$D,B30)) -> 0 | O30: =IF(B30="",0,SUMIFS(Changements!$B:$B,Changements!$A:$A,A30,Changements!$C:$C,B30)+IF(L30>M30,IFERROR(INDEX(Matchs!$F$4:$F$31,MATCH(A30,Matchs!$A$4:$A$31,0)),0),0)) -> 0 | P30: =IF(AND(B30<>"",C30="Oui"),1,0) -> 0 | Q30: =IF(AND(B30<>"",E30="Oui"),1,0) -> 0
A31: =INT((ROW()-4)/24)+1 -> 2 | B31: =INDEX('Effectif Saison'!$E$4:$E$22,4) -> Noé BIHL | F31: =IF(B31="","",IF(AND(E31="Oui",COUNTIFS(Changements!$A:$A,A31,Changements!$D:$D,B31)>0),"⚠ Titulaire+entrée ?",IF(ABS(L31-M31)>1,"⚠ vérifier",""))) | G31: =IF(B31="","",IFERROR(INDEX('Effectif Saison'!$D$4:$D$51,MATCH(B31,'Effectif Saison'!$E$4:$E$51,0)),"")) -> Équipe 1 | H31: =IF(L31=0,"",IF(E31="Oui",0,IFERROR(_xlfn.MINIFS(Changements!$B:$B,Changements!$A:$A,A31,Changements!$D:$D,B31),""))) | I31: =IF(M31=0,"",IFERROR(_xlfn.MAXIFS(Changements!$B:$B,Changements!$A:$A,A31,Changements!$C:$C,B31),"")) | J31: =IF(OR(B31="",C31<>"Oui"),"",O31-N31) | K31: =IF(AND(B31<>"",ISNUMBER(J31)),1,0) -> 0 | L31: =IF(B31="",0,COUNTIFS(Changements!$A:$A,A31,Changements!$D:$D,B31)+IF(E31="Oui",1,0)) -> 0 | M31: =IF(B31="",0,COUNTIFS(Changements!$A:$A,A31,Changements!$C:$C,B31)) -> 0 | N31: =IF(B31="",0,SUMIFS(Changements!$B:$B,Changements!$A:$A,A31,Changements!$D:$D,B31)) -> 0 | O31: =IF(B31="",0,SUMIFS(Changements!$B:$B,Changements!$A:$A,A31,Changements!$C:$C,B31)+IF(L31>M31,IFERROR(INDEX(Matchs!$F$4:$F$31,MATCH(A31,Matchs!$A$4:$A$31,0)),0),0)) -> 0 | P31: =IF(AND(B31<>"",C31="Oui"),1,0) -> 0 | Q31: =IF(AND(B31<>"",E31="Oui"),1,0) -> 0
A32: =INT((ROW()-4)/24)+1 -> 2 | B32: =INDEX('Effectif Saison'!$E$4:$E$22,5) -> Luca COLAIANNI | F32: =IF(B32="","",IF(AND(E32="Oui",COUNTIFS(Changements!$A:$A,A32,Changements!$D:$D,B32)>0),"⚠ Titulaire+entrée ?",IF(ABS(L32-M32)>1,"⚠ vérifier",""))) | G32: =IF(B32="","",IFERROR(INDEX('Effectif Saison'!$D$4:$D$51,MATCH(B32,'Effectif Saison'!$E$4:$E$51,0)),"")) -> Équipe 1 | H32: =IF(L32=0,"",IF(E32="Oui",0,IFERROR(_xlfn.MINIFS(Changements!$B:$B,Changements!$A:$A,A32,Changements!$D:$D,B32),""))) | I32: =IF(M32=0,"",IFERROR(_xlfn.MAXIFS(Changements!$B:$B,Changements!$A:$A,A32,Changements!$C:$C,B32),"")) | J32: =IF(OR(B32="",C32<>"Oui"),"",O32-N32) | K32: =IF(AND(B32<>"",ISNUMBER(J32)),1,0) -> 0 | L32: =IF(B32="",0,COUNTIFS(Changements!$A:$A,A32,Changements!$D:$D,B32)+IF(E32="Oui",1,0)) -> 0 | M32: =IF(B32="",0,COUNTIFS(Changements!$A:$A,A32,Changements!$C:$C,B32)) -> 0 | N32: =IF(B32="",0,SUMIFS(Changements!$B:$B,Changements!$A:$A,A32,Changements!$D:$D,B32)) -> 0 | O32: =IF(B32="",0,SUMIFS(Changements!$B:$B,Changements!$A:$A,A32,Changements!$C:$C,B32)+IF(L32>M32,IFERROR(INDEX(Matchs!$F$4:$F$31,MATCH(A32,Matchs!$A$4:$A$31,0)),0),0)) -> 0 | P32: =IF(AND(B32<>"",C32="Oui"),1,0) -> 0 | Q32: =IF(AND(B32<>"",E32="Oui"),1,0) -> 0
A33: =INT((ROW()-4)/24)+1 -> 2 | B33: =INDEX('Effectif Saison'!$E$4:$E$22,6) -> Atilla ER | F33: =IF(B33="","",IF(AND(E33="Oui",COUNTIFS(Changements!$A:$A,A33,Changements!$D:$D,B33)>0),"⚠ Titulaire+entrée ?",IF(ABS(L33-M33)>1,"⚠ vérifier",""))) | G33: =IF(B33="","",IFERROR(INDEX('Effectif Saison'!$D$4:$D$51,MATCH(B33,'Effectif Saison'!$E$4:$E$51,0)),"")) -> Équipe 1 | H33: =IF(L33=0,"",IF(E33="Oui",0,IFERROR(_xlfn.MINIFS(Changements!$B:$B,Changements!$A:$A,A33,Changements!$D:$D,B33),""))) | I33: =IF(M33=0,"",IFERROR(_xlfn.MAXIFS(Changements!$B:$B,Changements!$A:$A,A33,Changements!$C:$C,B33),"")) | J33: =IF(OR(B33="",C33<>"Oui"),"",O33-N33) | K33: =IF(AND(B33<>"",ISNUMBER(J33)),1,0) -> 0 | L33: =IF(B33="",0,COUNTIFS(Changements!$A:$A,A33,Changements!$D:$D,B33)+IF(E33="Oui",1,0)) -> 0 | M33: =IF(B33="",0,COUNTIFS(Changements!$A:$A,A33,Changements!$C:$C,B33)) -> 0 | N33: =IF(B33="",0,SUMIFS(Changements!$B:$B,Changements!$A:$A,A33,Changements!$D:$D,B33)) -> 0 | O33: =IF(B33="",0,SUMIFS(Changements!$B:$B,Changements!$A:$A,A33,Changements!$C:$C,B33)+IF(L33>M33,IFERROR(INDEX(Matchs!$F$4:$F$31,MATCH(A33,Matchs!$A$4:$A$31,0)),0),0)) -> 0 | P33: =IF(AND(B33<>"",C33="Oui"),1,0) -> 0 | Q33: =IF(AND(B33<>"",E33="Oui"),1,0) -> 0
A34: =INT((ROW()-4)/24)+1 -> 2 | B34: =INDEX('Effectif Saison'!$E$4:$E$22,7) -> Lucas BUHR | F34: =IF(B34="","",IF(AND(E34="Oui",COUNTIFS(Changements!$A:$A,A34,Changements!$D:$D,B34)>0),"⚠ Titulaire+entrée ?",IF(ABS(L34-M34)>1,"⚠ vérifier",""))) | G34: =IF(B34="","",IFERROR(INDEX('Effectif Saison'!$D$4:$D$51,MATCH(B34,'Effectif Saison'!$E$4:$E$51,0)),"")) -> Équipe 1 | H34: =IF(L34=0,"",IF(E34="Oui",0,IFERROR(_xlfn.MINIFS(Changements!$B:$B,Changements!$A:$A,A34,Changements!$D:$D,B34),""))) | I34: =IF(M34=0,"",IFERROR(_xlfn.MAXIFS(Changements!$B:$B,Changements!$A:$A,A34,Changements!$C:$C,B34),"")) | J34: =IF(OR(B34="",C34<>"Oui"),"",O34-N34) | K34: =IF(AND(B34<>"",ISNUMBER(J34)),1,0) -> 0 | L34: =IF(B34="",0,COUNTIFS(Changements!$A:$A,A34,Changements!$D:$D,B34)+IF(E34="Oui",1,0)) -> 0 | M34: =IF(B34="",0,COUNTIFS(Changements!$A:$A,A34,Changements!$C:$C,B34)) -> 0 | N34: =IF(B34="",0,SUMIFS(Changements!$B:$B,Changements!$A:$A,A34,Changements!$D:$D,B34)) -> 0 | O34: =IF(B34="",0,SUMIFS(Changements!$B:$B,Changements!$A:$A,A34,Changements!$C:$C,B34)+IF(L34>M34,IFERROR(INDEX(Matchs!$F$4:$F$31,MATCH(A34,Matchs!$A$4:$A$31,0)),0),0)) -> 0 | P34: =IF(AND(B34<>"",C34="Oui"),1,0) -> 0 | Q34: =IF(AND(B34<>"",E34="Oui"),1,0) -> 0
